Workbook

Sheet Raw_Data
A1: Customer ID | B1: Customer Name | C1: City | D1: Phone Number | E1: Email | F1: Gender | G1: Age
A2: C001 | B2: Rahul Sharma | C2: Delhi | D2: 9196361468 | E2: rahul.sharma@gmail.com | F2: Male | G2: 29
A3: C002 | B3: priya verma | C3: Ahmedabad | D3: 9501869335 | E3: priya.verma@gmail.com | F3: Female | G3: 29
A4: C003 | B4: RIYA SHARMA | C4: Jaipur | E4: riya.sharma@gmail.com | F4: Female | G4: 40
A5: C004 | B5: ROHIT GUPTA | C5: Lucknow | D5: 91280 | E5: rohit.gupta@gmail.com | F5: Male | G5: 30
A6: C005 | B6: VIKAS YADAV | D6: 9402823002 | E6: vikas.yadav@gmail.com | F6: Male | G6: 35
A7: C006 | B7: Neha Singh | C7: Chandigarh | D7: 9108933969 | F7: Female | G7: 37
A8: C007 | B8: Arjun Mehta | C8: Pune | D8: 9658582040 | E8: arjun.mehta@gmail.com | F8: Male | G8: 32
A9: C008 | B9: Mohan Das | C9: chandigarh | D9: 9087216808 | E9: mohan.das@gmail.com | F9: Male | G9: 43
A10: C009 | B10: Suresh Kumar | C10: Lucknow | D10: 94661 | E10: suresh.kumar@gmail.com | F10: Male | G10: 22
A11: C010 | B11: Rahul Sharma | C11: delhi | D11: 9488028597 | E11: rahul.sharma@gmail.com | F11: Male | G11: 22
A12: C011 | B12: Priya Verma | C12: Mumbai | D12: 9576153728 | E12: priya.verma@gmail.com | F12: Female | G12: 26
A13: C012 | B13: Pooja Sharma | C13: Jaipur | D13: 9255162375 | E13: pooja.sharma@gmail.com | F13: Female | G13: 27
A14: C013 | B14: Priya Verma | C14: Pune | D14: 9900188453 | E14: priya.verma@gmail.com | F14: Female | G14: 26
A15: C014 | B15: Priya Verma | C15: MUMBAI | D15: 9931544828 | F15: Female | G15: 30
A16: C015 | B16: Neha Singh | C16: Lucknow | D16: 9298313295 | E16: neha.singh@gmail.com | F16: Female | G16: 45
A17: C016 | B17: Sneha Roy | C17: Mumbai | D17: 9437088610 | E17: sneha.roy@gmail.com | F17: Female | G17: 28
A18: C017 | B18: Amit Kumar | D18: 9957918670 | E18: amit.kumar@gmail.com | F18: Male | G18: 34
A19: C018 | B19: amit kumar | C19: Ahmedabad | D19: 9297906224 | E19: amit.kumar@gmail.com | F19: Male | G19: 27
A20: C019 | B20: Karan Patel | C20: Ahmedabad | D20: 9300870608 | E20: karan.patel@gmail.com | F20: Male | G20: 32
A21: C020 | B21: Vikas Yadav | C21: Jaipur | D21: 9862003565 | E21: vikas.yadav@gmail.com | F21: Male | G21: 23
A22: C021 | B22: ANJALI GUPTA | C22: Mumbai | D22: 9102506354 | E22: anjali.gupta@gmail.com | F22: Female | G22: 34
A23: C022 | B23: Amit Kumar | C23: Mumbai | E23: amit.kumar@gmail.com | F23: Male | G23: 20
A24: C023 | B24: Neha Singh | C24: Jaipur | D24: 9654860251 | E24: neha.singh@gmail.com | F24: Female | G24: 24
A25: C024 | B25: Meena Joshi | C25: Ahmedabad | D25: 9049987722 | F25: Female | G25: 28
A26: C025 | B26: Karan Patel | C26: Jaipur | D26: 9158149443 | E26: karan.patel@gmail.com | F26: Male | G26: 36
A27: C026 | B27: Rahul Sharma | D27: 9423352933 | E27: rahul.sharma@gmail.com | F27: Male | G27: 39
A28: C027 | B28: suresh kumar | C28: Jaipur | D28: 9991044441 | E28: suresh.kumar@gmail.com | F28: Male | G28: 22
A29: C028 | B29: pooja sharma | C29: delhi | D29: 9882586258 | F29: Female | G29: 38
A30: C029 | B30: Priya Verma | C30: pune | D30: 9246972866 | F30: Female | G30: 34
A31: C030 | B31: Priya Verma | C31: lucknow | D31: 9399901936 | E31: priya.verma@gmail.com | F31: Female | G31: 26
A32: C031 | B32: Meena Joshi | C32: Ahmedabad | D32: 97306 | E32: meena.joshi@gmail.com | F32: Female | G32: 41
A33: C032 | B33: Priya Verma | C33: delhi | D33: 9676533700 | E33: priya.verma@gmail.com | F33: Female | G33: 36
A34: C033 | B34: priya verma | C34: Jaipur | E34: priya.verma@gmail.com | F34: Female | G34: 23
A35: C034 | B35: Karan Patel | C35: Ahmedabad | D35: 9026670894 | E35: karan.patel@gmail.com | F35: Male | G35: 20
A36: C035 | B36: Amit Kumar | C36: Delhi | D36: 9921682683 | E36: amit.kumar@gmail.com | F36: Male | G36: 38
A37: C036 | B37: SURESH KUMAR | C37: Pune | D37: 97216 | E37: suresh.kumar@gmail.com | F37: Male | G37: 33
A38: C037 | B38: Meena Joshi | C38: Mumbai | D38: 9680434757 | E38: meena.joshi@gmail.com | F38: Female | G38: 29
A39: C038 | B39: Suresh Kumar | C39: Lucknow | D39: 93711 | E39: suresh.kumar@gmail.com | F39: Male | G39: 38
A40: C039 | B40: Meena Joshi | C40: Chandigarh | D40: 9647022412 | E40: meena.joshi@gmail.com | F40: Female | G40: 37
...

Sheet clean data
A1: Customer ID | B1: customer name | C1: City | D1: Phone Number | E1: Phone status | F1: Email | G1: Gender | H1: Age | I1: Age Group
A2: C001 | B2: Rahul Sharma | C2: Delhi | D2: 9196361468 | E2: =IF(D2="","Blank",IF(LEN(D2)=10,"valid","invalid")) -> valid | F2: rahul.sharma@gmail.com | G2: Male | H2: 29 | I2: {=_xlfn.IFS(H2:H101<=25,"Young",H2:H101<=35,"Adult",H2:H101>=36,"Senior")} -> Adult
A3: C002 | B3: Priya Verma | C3: Ahmedabad | D3: 9501869335 | E3: =IF(D3="","Blank",IF(LEN(D3)=10,"valid","invalid")) -> valid | F3: priya.verma@gmail.com | G3: Female | H3: 29 | I3: Adult
A4: C003 | B4: Riya Sharma | C4: Jaipur | E4: =IF(D4="","Blank",IF(LEN(D4)=10,"valid","invalid")) -> Blank | F4: riya.sharma@gmail.com | G4: Female | H4: 40 | I4: Senior
A5: C004 | B5: Rohit Gupta | C5: Lucknow | D5: 91280 | E5: =IF(D5="","Blank",IF(LEN(D5)=10,"valid","invalid")) -> invalid | F5: rohit.gupta@gmail.com | G5: Male | H5: 30 | I5: Adult
A6: C005 | B6: Vikas Yadav | D6: 9402823002 | E6: =IF(D6="","Blank",IF(LEN(D6)=10,"valid","invalid")) -> valid | F6: vikas.yadav@gmail.com | G6: Male | H6: 35 | I6: Adult
A7: C006 | B7: Neha Singh | C7: Chandigarh | D7: 9108933969 | E7: =IF(D7="","Blank",IF(LEN(D7)=10,"valid","invalid")) -> valid | G7: Female | H7: 37 | I7: Senior
A8: C007 | B8: Arjun Mehta | C8: Pune | D8: 9658582040 | E8: =IF(D8="","Blank",IF(LEN(D8)=10,"valid","invalid")) -> valid | F8: arjun.mehta@gmail.com | G8: Male | H8: 32 | I8: Adult
A9: C008 | B9: Mohan Das | C9: Chandigarh | D9: 9087216808 | E9: =IF(D9="","Blank",IF(LEN(D9)=10,"valid","invalid")) -> valid | F9: mohan.das@gmail.com | G9: Male | H9: 43 | I9: Senior
A10: C009 | B10: Suresh Kumar | C10: Lucknow | D10: 94661 | E10: =IF(D10="","Blank",IF(LEN(D10)=10,"valid","invalid")) -> invalid | F10: suresh.kumar@gmail.com | G10: Male | H10: 22 | I10: Young
A11: C010 | B11: Rahul Sharma | C11: Delhi | D11: 9488028597 | E11: =IF(D11="","Blank",IF(LEN(D11)=10,"valid","invalid")) -> valid | F11: rahul.sharma@gmail.com | G11: Male | H11: 22 | I11: Young
A12: C011 | B12: Priya Verma | C12: Mumbai | D12: 9576153728 | E12: =IF(D12="","Blank",IF(LEN(D12)=10,"valid","invalid")) -> valid | F12: priya.verma@gmail.com | G12: Female | H12: 26 | I12: Adult
A13: C012 | B13: Pooja Sharma | C13: Jaipur | D13: 9255162375 | E13: =IF(D13="","Blank",IF(LEN(D13)=10,"valid","invalid")) -> valid | F13: pooja.sharma@gmail.com | G13: Female | H13: 27 | I13: Adult
A14: C013 | B14: Priya Verma | C14: Pune | D14: 9900188453 | E14: =IF(D14="","Blank",IF(LEN(D14)=10,"valid","invalid")) -> valid | F14: priya.verma@gmail.com | G14: Female | H14: 26 | I14: Adult
A15: C014 | B15: Priya Verma | C15: Mumbai | D15: 9931544828 | E15: =IF(D15="","Blank",IF(LEN(D15)=10,"valid","invalid")) -> valid | G15: Female | H15: 30 | I15: Adult
A16: C015 | B16: Neha Singh | C16: Lucknow | D16: 9298313295 | E16: =IF(D16="","Blank",IF(LEN(D16)=10,"valid","invalid")) -> valid | F16: neha.singh@gmail.com | G16: Female | H16: 45 | I16: Senior
A17: C016 | B17: Sneha Roy | C17: Mumbai | D17: 9437088610 | E17: =IF(D17="","Blank",IF(LEN(D17)=10,"valid","invalid")) -> valid | F17: sneha.roy@gmail.com | G17: Female | H17: 28 | I17: Adult
A18: C017 | B18: Amit Kumar | D18: 9957918670 | E18: =IF(D18="","Blank",IF(LEN(D18)=10,"valid","invalid")) -> valid | F18: amit.kumar@gmail.com | G18: Male | H18: 34 | I18: Adult
A19: C018 | B19: Amit Kumar | C19: Ahmedabad | D19: 9297906224 | E19: =IF(D19="","Blank",IF(LEN(D19)=10,"valid","invalid")) -> valid | F19: amit.kumar@gmail.com | G19: Male | H19: 27 | I19: Adult
A20: C019 | B20: Karan Patel | C20: Ahmedabad | D20: 9300870608 | E20: =IF(D20="","Blank",IF(LEN(D20)=10,"valid","invalid")) -> valid | F20: karan.patel@gmail.com | G20: Male | H20: 32 | I20: Adult
A21: C020 | B21: Vikas Yadav | C21: Jaipur | D21: 9862003565 | E21: =IF(D21="","Blank",IF(LEN(D21)=10,"valid","invalid")) -> valid | F21: vikas.yadav@gmail.com | G21: Male | H21: 23 | I21: Young
A22: C021 | B22: Anjali Gupta | C22: Mumbai | D22: 9102506354 | E22: =IF(D22="","Blank",IF(LEN(D22)=10,"valid","invalid")) -> valid | F22: anjali.gupta@gmail.com | G22: Female | H22: 34 | I22: Adult
A23: C022 | B23: Amit Kumar | C23: Mumbai | E23: =IF(D23="","Blank",IF(LEN(D23)=10,"valid","invalid")) -> Blank | F23: amit.kumar@gmail.com | G23: Male | H23: 20 | I23: Young
A24: C023 | B24: Neha Singh | C24: Jaipur | D24: 9654860251 | E24: =IF(D24="","Blank",IF(LEN(D24)=10,"valid","invalid")) -> valid | F24: neha.singh@gmail.com | G24: Female | H24: 24 | I24: Young
A25: C024 | B25: Meena Joshi | C25: Ahmedabad | D25: 9049987722 | E25: =IF(D25="","Blank",IF(LEN(D25)=10,"valid","invalid")) -> valid | G25: Female | H25: 28 | I25: Adult
A26: C025 | B26: Karan Patel | C26: Jaipur | D26: 9158149443 | E26: =IF(D26="","Blank",IF(LEN(D26)=10,"valid","invalid")) -> valid | F26: karan.patel@gmail.com | G26: Male | H26: 36 | I26: Senior
A27: C026 | B27: Rahul Sharma | D27: 9423352933 | E27: =IF(D27="","Blank",IF(LEN(D27)=10,"valid","invalid")) -> valid | F27: rahul.sharma@gmail.com | G27: Male | H27: 39 | I27: Senior
A28: C027 | B28: Suresh Kumar | C28: Jaipur | D28: 9991044441 | E28: =IF(D28="","Blank",IF(LEN(D28)=10,"valid","invalid")) -> valid | F28: suresh.kumar@gmail.com | G28: Male | H28: 22 | I28: Young
A29: C028 | B29: Pooja Sharma | C29: Delhi | D29: 9882586258 | E29: =IF(D29="","Blank",IF(LEN(D29)=10,"valid","invalid")) -> valid | G29: Female | H29: 38 | I29: Senior
A30: C029 | B30: Priya Verma | C30: Pune | D30: 9246972866 | E30: =IF(D30="","Blank",IF(LEN(D30)=10,"valid","invalid")) -> valid | G30: Female | H30: 34 | I30: Adult
A31: C030 | B31: Priya Verma | C31: Lucknow | D31: 9399901936 | E31: =IF(D31="","Blank",IF(LEN(D31)=10,"valid","invalid")) -> valid | F31: priya.verma@gmail.com | G31: Female | H31: 26 | I31: Adult
A32: C031 | B32: Meena Joshi | C32: Ahmedabad | D32: 97306 | E32: =IF(D32="","Blank",IF(LEN(D32)=10,"valid","invalid")) -> invalid | F32: meena.joshi@gmail.com | G32: Female | H32: 41 | I32: Senior
A33: C032 | B33: Priya Verma | C33: Delhi | D33: 9676533700 | E33: =IF(D33="","Blank",IF(LEN(D33)=10,"valid","invalid")) -> valid | F33: priya.verma@gmail.com | G33: Female | H33: 36 | I33: Senior
A34: C033 | B34: Priya Verma | C34: Jaipur | E34: =IF(D34="","Blank",IF(LEN(D34)=10,"valid","invalid")) -> Blank | F34: priya.verma@gmail.com | G34: Female | H34: 23 | I34: Young
A35: C034 | B35: Karan Patel | C35: Ahmedabad | D35: 9026670894 | E35: =IF(D35="","Blank",IF(LEN(D35)=10,"valid","invalid")) -> valid | F35: karan.patel@gmail.com | G35: Male | H35: 20 | I35: Young
A36: C035 | B36: Amit Kumar | C36: Delhi | D36: 9921682683 | E36: =IF(D36="","Blank",IF(LEN(D36)=10,"valid","invalid")) -> valid | F36: amit.kumar@gmail.com | G36: Male | H36: 38 | I36: Senior
A37: C036 | B37: Suresh Kumar | C37: Pune | D37: 97216 | E37: =IF(D37="","Blank",IF(LEN(D37)=10,"valid","invalid")) -> invalid | F37: suresh.kumar@gmail.com | G37: Male | H37: 33 | I37: Adult
A38: C037 | B38: Meena Joshi | C38: Mumbai | D38: 9680434757 | E38: =IF(D38="","Blank",IF(LEN(D38)=10,"valid","invalid")) -> valid | F38: meena.joshi@gmail.com | G38: Female | H38: 29 | I38: Adult
A39: C038 | B39: Suresh Kumar | C39: Lucknow | D39: 93711 | E39: =IF(D39="","Blank",IF(LEN(D39)=10,"valid","invalid")) -> invalid | F39: suresh.kumar@gmail.com | G39: Male | H39: 38 | I39: Senior
A40: C039 | B40: Meena Joshi | C40: Chandigarh | D40: 9647022412 | E40: =IF(D40="","Blank",IF(LEN(D40)=10,"valid","invalid")) -> valid | F40: meena.joshi@gmail.com | G40: Female | H40: 37 | I40: Senior
...

Sheet summary
E4: SUMMARY
E6: Total Customer | F6: =COUNTA([1]Clean_data!A2:A101) -> 100
E8: Duplicate Records | F8: 5
E10: Blank Cities | F10: =COUNTBLANK('clean data'!C2:C101) -> 6
E12: Blank Email | F12: =COUNTBLANK('clean data'!F2:F101) -> 8
E14: Valid Phone number | F14: =COUNTIF('clean data'!E2:E101,"Valid") -> 89
E16: Invalid Phone number | F16: =COUNTIF('clean data'!E2:E101,"Invalid") -> 7
E18: Blank Phone number | F18: =COUNTIF('clean data'!E2:E101,"Blank") -> 4
